<?xml version="1.0"?>
<robot xmlns:xacro="http://www.ros.org/wiki/xacro" name="wheel">

    <xacro:macro name="wheel" params="name inertial_xyz joint_xyz">
        <link name="${name}_wheel">
            <inertial>
                <origin xyz="${inertial_xyz}" rpy="0 0 0" />
                <mass value="0.99202" />
                <inertia ixx="0.0017289" ixy="-1.1999E-19" ixz="2.0419E-19"
                         iyy="0.0030122" iyz="4.5246E-18" izz="0.0017289" />
            </inertial>
            <visual>
                <origin xyz="0 0 0" rpy="0 0 0" />
                <geometry>
                    <mesh filename="package://agv_description/meshes/${name}_wheel.STL" />
                </geometry>
                <material name="">
                    <color rgba="0.79216 0.81961 0.93333 1" />
                </material>
            </visual>
            <collision>
                <origin xyz="0 0 0" rpy="0 0 0" />
                <geometry>
                    <mesh filename="package://agv_description/meshes/${name}_wheel.STL" />
                </geometry>
            </collision>
        </link>

        <joint name="base_to_${name}_wheel" type="continuous">
            <origin xyz="${joint_xyz}" rpy="0 0 0" />
            <parent link="base_link" />
            <child link="${name}_wheel" />
            <axis xyz="0 1 0" />
        </joint>
    </xacro:macro>

</robot>